{
 "cells": [
  {
   "cell_type": "code",
   "execution_count": 1,
   "metadata": {},
   "outputs": [
    {
     "name": "stderr",
     "output_type": "stream",
     "text": [
      "/Users/yihaoli/opt/anaconda3/lib/python3.7/site-packages/tensorflow/python/framework/dtypes.py:516: FutureWarning: Passing (type, 1) or '1type' as a synonym of type is deprecated; in a future version of numpy, it will be understood as (type, (1,)) / '(1,)type'.\n",
      "  _np_qint8 = np.dtype([(\"qint8\", np.int8, 1)])\n",
      "/Users/yihaoli/opt/anaconda3/lib/python3.7/site-packages/tensorflow/python/framework/dtypes.py:517: FutureWarning: Passing (type, 1) or '1type' as a synonym of type is deprecated; in a future version of numpy, it will be understood as (type, (1,)) / '(1,)type'.\n",
      "  _np_quint8 = np.dtype([(\"quint8\", np.uint8, 1)])\n",
      "/Users/yihaoli/opt/anaconda3/lib/python3.7/site-packages/tensorflow/python/framework/dtypes.py:518: FutureWarning: Passing (type, 1) or '1type' as a synonym of type is deprecated; in a future version of numpy, it will be understood as (type, (1,)) / '(1,)type'.\n",
      "  _np_qint16 = np.dtype([(\"qint16\", np.int16, 1)])\n",
      "/Users/yihaoli/opt/anaconda3/lib/python3.7/site-packages/tensorflow/python/framework/dtypes.py:519: FutureWarning: Passing (type, 1) or '1type' as a synonym of type is deprecated; in a future version of numpy, it will be understood as (type, (1,)) / '(1,)type'.\n",
      "  _np_quint16 = np.dtype([(\"quint16\", np.uint16, 1)])\n",
      "/Users/yihaoli/opt/anaconda3/lib/python3.7/site-packages/tensorflow/python/framework/dtypes.py:520: FutureWarning: Passing (type, 1) or '1type' as a synonym of type is deprecated; in a future version of numpy, it will be understood as (type, (1,)) / '(1,)type'.\n",
      "  _np_qint32 = np.dtype([(\"qint32\", np.int32, 1)])\n",
      "/Users/yihaoli/opt/anaconda3/lib/python3.7/site-packages/tensorflow/python/framework/dtypes.py:525: FutureWarning: Passing (type, 1) or '1type' as a synonym of type is deprecated; in a future version of numpy, it will be understood as (type, (1,)) / '(1,)type'.\n",
      "  np_resource = np.dtype([(\"resource\", np.ubyte, 1)])\n",
      "/Users/yihaoli/opt/anaconda3/lib/python3.7/site-packages/tensorboard/compat/tensorflow_stub/dtypes.py:541: FutureWarning: Passing (type, 1) or '1type' as a synonym of type is deprecated; in a future version of numpy, it will be understood as (type, (1,)) / '(1,)type'.\n",
      "  _np_qint8 = np.dtype([(\"qint8\", np.int8, 1)])\n",
      "/Users/yihaoli/opt/anaconda3/lib/python3.7/site-packages/tensorboard/compat/tensorflow_stub/dtypes.py:542: FutureWarning: Passing (type, 1) or '1type' as a synonym of type is deprecated; in a future version of numpy, it will be understood as (type, (1,)) / '(1,)type'.\n",
      "  _np_quint8 = np.dtype([(\"quint8\", np.uint8, 1)])\n",
      "/Users/yihaoli/opt/anaconda3/lib/python3.7/site-packages/tensorboard/compat/tensorflow_stub/dtypes.py:543: FutureWarning: Passing (type, 1) or '1type' as a synonym of type is deprecated; in a future version of numpy, it will be understood as (type, (1,)) / '(1,)type'.\n",
      "  _np_qint16 = np.dtype([(\"qint16\", np.int16, 1)])\n",
      "/Users/yihaoli/opt/anaconda3/lib/python3.7/site-packages/tensorboard/compat/tensorflow_stub/dtypes.py:544: FutureWarning: Passing (type, 1) or '1type' as a synonym of type is deprecated; in a future version of numpy, it will be understood as (type, (1,)) / '(1,)type'.\n",
      "  _np_quint16 = np.dtype([(\"quint16\", np.uint16, 1)])\n",
      "/Users/yihaoli/opt/anaconda3/lib/python3.7/site-packages/tensorboard/compat/tensorflow_stub/dtypes.py:545: FutureWarning: Passing (type, 1) or '1type' as a synonym of type is deprecated; in a future version of numpy, it will be understood as (type, (1,)) / '(1,)type'.\n",
      "  _np_qint32 = np.dtype([(\"qint32\", np.int32, 1)])\n",
      "/Users/yihaoli/opt/anaconda3/lib/python3.7/site-packages/tensorboard/compat/tensorflow_stub/dtypes.py:550: FutureWarning: Passing (type, 1) or '1type' as a synonym of type is deprecated; in a future version of numpy, it will be understood as (type, (1,)) / '(1,)type'.\n",
      "  np_resource = np.dtype([(\"resource\", np.ubyte, 1)])\n"
     ]
    }
   ],
   "source": [
    "import os\n",
    "import sys\n",
    "import ocr\n",
    "import time\n",
    "import shutil\n",
    "import cv2\n",
    "import math\n",
    "import numpy as np\n",
    "from PIL import Image\n",
    "from glob import glob\n",
    "import fengzhuang_chinese_ocr\n",
    "import seg_resize as sg\n",
    "from matplotlib import pyplot as plt\n",
    "%matplotlib inline\n",
    "plt.rcParams['figure.figsize'] = (20, 10)"
   ]
  },
  {
   "cell_type": "markdown",
   "metadata": {},
   "source": [
    "## 1. load the receipts and do segmentation"
   ]
  },
  {
   "cell_type": "code",
   "execution_count": 7,
   "metadata": {},
   "outputs": [],
   "source": [
    "image_files = glob('./receipts/*.*')\n",
    "# image_files = glob('./test_images/*.*')\n",
    "out_path = './res_receipts'"
   ]
  },
  {
   "cell_type": "code",
   "execution_count": 8,
   "metadata": {},
   "outputs": [
    {
     "data": {
      "text/plain": [
       "['./receipts/shhsh_10201723_201_20200418130334_1_711652.png',\n",
       " './receipts/bjcyhsh_10223208_201_20200604164041_1_299498.png']"
      ]
     },
     "execution_count": 8,
     "metadata": {},
     "output_type": "execute_result"
    }
   ],
   "source": [
    "image_files"
   ]
  },
  {
   "cell_type": "code",
   "execution_count": 3,
   "metadata": {},
   "outputs": [
    {
     "name": "stdout",
     "output_type": "stream",
     "text": [
      "shhsh_10201723_201_20200418130334_1_711652\n"
     ]
    }
   ],
   "source": [
    "file_in = './receipts/shhsh_10201723_201_20200418130334_1_711652.png'\n",
    "print(os.path.basename(file_in).split('.')[0])"
   ]
  },
  {
   "cell_type": "code",
   "execution_count": 9,
   "metadata": {},
   "outputs": [],
   "source": [
    "if os.path.exists(out_path):\n",
    "        shutil.rmtree(out_path)\n",
    "os.mkdir(out_path)"
   ]
  },
  {
   "cell_type": "code",
   "execution_count": 10,
   "metadata": {},
   "outputs": [
    {
     "name": "stdout",
     "output_type": "stream",
     "text": [
      "WARNING:tensorflow:Entity <bound method Conv.call of <tensorflow.python.layers.convolutional.Conv2D object at 0x1504dc150>> could not be transformed and will be executed as-is. Please report this to the AutgoGraph team. When filing the bug, set the verbosity to 10 (on Linux, `export AUTOGRAPH_VERBOSITY=10`) and attach the full output. Cause: converting <bound method Conv.call of <tensorflow.python.layers.convolutional.Conv2D object at 0x1504dc150>>: AssertionError: Bad argument number for Name: 3, expecting 4\n",
      "WARNING: Entity <bound method Conv.call of <tensorflow.python.layers.convolutional.Conv2D object at 0x1504dc150>> could not be transformed and will be executed as-is. Please report this to the AutgoGraph team. When filing the bug, set the verbosity to 10 (on Linux, `export AUTOGRAPH_VERBOSITY=10`) and attach the full output. Cause: converting <bound method Conv.call of <tensorflow.python.layers.convolutional.Conv2D object at 0x1504dc150>>: AssertionError: Bad argument number for Name: 3, expecting 4\n",
      "WARNING:tensorflow:Entity <bound method Conv.call of <tensorflow.python.layers.convolutional.Conv2D object at 0x1504dc790>> could not be transformed and will be executed as-is. Please report this to the AutgoGraph team. When filing the bug, set the verbosity to 10 (on Linux, `export AUTOGRAPH_VERBOSITY=10`) and attach the full output. Cause: converting <bound method Conv.call of <tensorflow.python.layers.convolutional.Conv2D object at 0x1504dc790>>: AssertionError: Bad argument number for Name: 3, expecting 4\n",
      "WARNING: Entity <bound method Conv.call of <tensorflow.python.layers.convolutional.Conv2D object at 0x1504dc790>> could not be transformed and will be executed as-is. Please report this to the AutgoGraph team. When filing the bug, set the verbosity to 10 (on Linux, `export AUTOGRAPH_VERBOSITY=10`) and attach the full output. Cause: converting <bound method Conv.call of <tensorflow.python.layers.convolutional.Conv2D object at 0x1504dc790>>: AssertionError: Bad argument number for Name: 3, expecting 4\n",
      "WARNING:tensorflow:Entity <bound method Pooling2D.call of <tensorflow.python.layers.pooling.MaxPooling2D object at 0x15030b610>> could not be transformed and will be executed as-is. Please report this to the AutgoGraph team. When filing the bug, set the verbosity to 10 (on Linux, `export AUTOGRAPH_VERBOSITY=10`) and attach the full output. Cause: converting <bound method Pooling2D.call of <tensorflow.python.layers.pooling.MaxPooling2D object at 0x15030b610>>: AssertionError: Bad argument number for Name: 3, expecting 4\n",
      "WARNING: Entity <bound method Pooling2D.call of <tensorflow.python.layers.pooling.MaxPooling2D object at 0x15030b610>> could not be transformed and will be executed as-is. Please report this to the AutgoGraph team. When filing the bug, set the verbosity to 10 (on Linux, `export AUTOGRAPH_VERBOSITY=10`) and attach the full output. Cause: converting <bound method Pooling2D.call of <tensorflow.python.layers.pooling.MaxPooling2D object at 0x15030b610>>: AssertionError: Bad argument number for Name: 3, expecting 4\n",
      "WARNING:tensorflow:Entity <bound method Conv.call of <tensorflow.python.layers.convolutional.Conv2D object at 0x1504dc8d0>> could not be transformed and will be executed as-is. Please report this to the AutgoGraph team. When filing the bug, set the verbosity to 10 (on Linux, `export AUTOGRAPH_VERBOSITY=10`) and attach the full output. Cause: converting <bound method Conv.call of <tensorflow.python.layers.convolutional.Conv2D object at 0x1504dc8d0>>: AssertionError: Bad argument number for Name: 3, expecting 4\n",
      "WARNING: Entity <bound method Conv.call of <tensorflow.python.layers.convolutional.Conv2D object at 0x1504dc8d0>> could not be transformed and will be executed as-is. Please report this to the AutgoGraph team. When filing the bug, set the verbosity to 10 (on Linux, `export AUTOGRAPH_VERBOSITY=10`) and attach the full output. Cause: converting <bound method Conv.call of <tensorflow.python.layers.convolutional.Conv2D object at 0x1504dc8d0>>: AssertionError: Bad argument number for Name: 3, expecting 4\n",
      "WARNING:tensorflow:Entity <bound method Conv.call of <tensorflow.python.layers.convolutional.Conv2D object at 0x1504dc110>> could not be transformed and will be executed as-is. Please report this to the AutgoGraph team. When filing the bug, set the verbosity to 10 (on Linux, `export AUTOGRAPH_VERBOSITY=10`) and attach the full output. Cause: converting <bound method Conv.call of <tensorflow.python.layers.convolutional.Conv2D object at 0x1504dc110>>: AssertionError: Bad argument number for Name: 3, expecting 4\n",
      "WARNING: Entity <bound method Conv.call of <tensorflow.python.layers.convolutional.Conv2D object at 0x1504dc110>> could not be transformed and will be executed as-is. Please report this to the AutgoGraph team. When filing the bug, set the verbosity to 10 (on Linux, `export AUTOGRAPH_VERBOSITY=10`) and attach the full output. Cause: converting <bound method Conv.call of <tensorflow.python.layers.convolutional.Conv2D object at 0x1504dc110>>: AssertionError: Bad argument number for Name: 3, expecting 4\n",
      "WARNING:tensorflow:Entity <bound method Pooling2D.call of <tensorflow.python.layers.pooling.MaxPooling2D object at 0x15030b610>> could not be transformed and will be executed as-is. Please report this to the AutgoGraph team. When filing the bug, set the verbosity to 10 (on Linux, `export AUTOGRAPH_VERBOSITY=10`) and attach the full output. Cause: converting <bound method Pooling2D.call of <tensorflow.python.layers.pooling.MaxPooling2D object at 0x15030b610>>: AssertionError: Bad argument number for Name: 3, expecting 4\n",
      "WARNING: Entity <bound method Pooling2D.call of <tensorflow.python.layers.pooling.MaxPooling2D object at 0x15030b610>> could not be transformed and will be executed as-is. Please report this to the AutgoGraph team. When filing the bug, set the verbosity to 10 (on Linux, `export AUTOGRAPH_VERBOSITY=10`) and attach the full output. Cause: converting <bound method Pooling2D.call of <tensorflow.python.layers.pooling.MaxPooling2D object at 0x15030b610>>: AssertionError: Bad argument number for Name: 3, expecting 4\n",
      "WARNING:tensorflow:Entity <bound method Conv.call of <tensorflow.python.layers.convolutional.Conv2D object at 0x1504dca90>> could not be transformed and will be executed as-is. Please report this to the AutgoGraph team. When filing the bug, set the verbosity to 10 (on Linux, `export AUTOGRAPH_VERBOSITY=10`) and attach the full output. Cause: converting <bound method Conv.call of <tensorflow.python.layers.convolutional.Conv2D object at 0x1504dca90>>: AssertionError: Bad argument number for Name: 3, expecting 4\n",
      "WARNING: Entity <bound method Conv.call of <tensorflow.python.layers.convolutional.Conv2D object at 0x1504dca90>> could not be transformed and will be executed as-is. Please report this to the AutgoGraph team. When filing the bug, set the verbosity to 10 (on Linux, `export AUTOGRAPH_VERBOSITY=10`) and attach the full output. Cause: converting <bound method Conv.call of <tensorflow.python.layers.convolutional.Conv2D object at 0x1504dca90>>: AssertionError: Bad argument number for Name: 3, expecting 4\n",
      "WARNING:tensorflow:Entity <bound method Conv.call of <tensorflow.python.layers.convolutional.Conv2D object at 0x1504dc510>> could not be transformed and will be executed as-is. Please report this to the AutgoGraph team. When filing the bug, set the verbosity to 10 (on Linux, `export AUTOGRAPH_VERBOSITY=10`) and attach the full output. Cause: converting <bound method Conv.call of <tensorflow.python.layers.convolutional.Conv2D object at 0x1504dc510>>: AssertionError: Bad argument number for Name: 3, expecting 4\n",
      "WARNING: Entity <bound method Conv.call of <tensorflow.python.layers.convolutional.Conv2D object at 0x1504dc510>> could not be transformed and will be executed as-is. Please report this to the AutgoGraph team. When filing the bug, set the verbosity to 10 (on Linux, `export AUTOGRAPH_VERBOSITY=10`) and attach the full output. Cause: converting <bound method Conv.call of <tensorflow.python.layers.convolutional.Conv2D object at 0x1504dc510>>: AssertionError: Bad argument number for Name: 3, expecting 4\n"
     ]
    },
    {
     "name": "stdout",
     "output_type": "stream",
     "text": [
      "WARNING:tensorflow:Entity <bound method Conv.call of <tensorflow.python.layers.convolutional.Conv2D object at 0x1504dc610>> could not be transformed and will be executed as-is. Please report this to the AutgoGraph team. When filing the bug, set the verbosity to 10 (on Linux, `export AUTOGRAPH_VERBOSITY=10`) and attach the full output. Cause: converting <bound method Conv.call of <tensorflow.python.layers.convolutional.Conv2D object at 0x1504dc610>>: AssertionError: Bad argument number for Name: 3, expecting 4\n",
      "WARNING: Entity <bound method Conv.call of <tensorflow.python.layers.convolutional.Conv2D object at 0x1504dc610>> could not be transformed and will be executed as-is. Please report this to the AutgoGraph team. When filing the bug, set the verbosity to 10 (on Linux, `export AUTOGRAPH_VERBOSITY=10`) and attach the full output. Cause: converting <bound method Conv.call of <tensorflow.python.layers.convolutional.Conv2D object at 0x1504dc610>>: AssertionError: Bad argument number for Name: 3, expecting 4\n",
      "WARNING:tensorflow:Entity <bound method Pooling2D.call of <tensorflow.python.layers.pooling.MaxPooling2D object at 0x15029aa90>> could not be transformed and will be executed as-is. Please report this to the AutgoGraph team. When filing the bug, set the verbosity to 10 (on Linux, `export AUTOGRAPH_VERBOSITY=10`) and attach the full output. Cause: converting <bound method Pooling2D.call of <tensorflow.python.layers.pooling.MaxPooling2D object at 0x15029aa90>>: AssertionError: Bad argument number for Name: 3, expecting 4\n",
      "WARNING: Entity <bound method Pooling2D.call of <tensorflow.python.layers.pooling.MaxPooling2D object at 0x15029aa90>> could not be transformed and will be executed as-is. Please report this to the AutgoGraph team. When filing the bug, set the verbosity to 10 (on Linux, `export AUTOGRAPH_VERBOSITY=10`) and attach the full output. Cause: converting <bound method Pooling2D.call of <tensorflow.python.layers.pooling.MaxPooling2D object at 0x15029aa90>>: AssertionError: Bad argument number for Name: 3, expecting 4\n",
      "WARNING:tensorflow:Entity <bound method Conv.call of <tensorflow.python.layers.convolutional.Conv2D object at 0x14ffdead0>> could not be transformed and will be executed as-is. Please report this to the AutgoGraph team. When filing the bug, set the verbosity to 10 (on Linux, `export AUTOGRAPH_VERBOSITY=10`) and attach the full output. Cause: converting <bound method Conv.call of <tensorflow.python.layers.convolutional.Conv2D object at 0x14ffdead0>>: AssertionError: Bad argument number for Name: 3, expecting 4\n",
      "WARNING: Entity <bound method Conv.call of <tensorflow.python.layers.convolutional.Conv2D object at 0x14ffdead0>> could not be transformed and will be executed as-is. Please report this to the AutgoGraph team. When filing the bug, set the verbosity to 10 (on Linux, `export AUTOGRAPH_VERBOSITY=10`) and attach the full output. Cause: converting <bound method Conv.call of <tensorflow.python.layers.convolutional.Conv2D object at 0x14ffdead0>>: AssertionError: Bad argument number for Name: 3, expecting 4\n",
      "WARNING:tensorflow:Entity <bound method Conv.call of <tensorflow.python.layers.convolutional.Conv2D object at 0x1501116d0>> could not be transformed and will be executed as-is. Please report this to the AutgoGraph team. When filing the bug, set the verbosity to 10 (on Linux, `export AUTOGRAPH_VERBOSITY=10`) and attach the full output. Cause: converting <bound method Conv.call of <tensorflow.python.layers.convolutional.Conv2D object at 0x1501116d0>>: AssertionError: Bad argument number for Name: 3, expecting 4\n",
      "WARNING: Entity <bound method Conv.call of <tensorflow.python.layers.convolutional.Conv2D object at 0x1501116d0>> could not be transformed and will be executed as-is. Please report this to the AutgoGraph team. When filing the bug, set the verbosity to 10 (on Linux, `export AUTOGRAPH_VERBOSITY=10`) and attach the full output. Cause: converting <bound method Conv.call of <tensorflow.python.layers.convolutional.Conv2D object at 0x1501116d0>>: AssertionError: Bad argument number for Name: 3, expecting 4\n",
      "WARNING:tensorflow:Entity <bound method Conv.call of <tensorflow.python.layers.convolutional.Conv2D object at 0x150284250>> could not be transformed and will be executed as-is. Please report this to the AutgoGraph team. When filing the bug, set the verbosity to 10 (on Linux, `export AUTOGRAPH_VERBOSITY=10`) and attach the full output. Cause: converting <bound method Conv.call of <tensorflow.python.layers.convolutional.Conv2D object at 0x150284250>>: AssertionError: Bad argument number for Name: 3, expecting 4\n",
      "WARNING: Entity <bound method Conv.call of <tensorflow.python.layers.convolutional.Conv2D object at 0x150284250>> could not be transformed and will be executed as-is. Please report this to the AutgoGraph team. When filing the bug, set the verbosity to 10 (on Linux, `export AUTOGRAPH_VERBOSITY=10`) and attach the full output. Cause: converting <bound method Conv.call of <tensorflow.python.layers.convolutional.Conv2D object at 0x150284250>>: AssertionError: Bad argument number for Name: 3, expecting 4\n",
      "WARNING:tensorflow:Entity <bound method Pooling2D.call of <tensorflow.python.layers.pooling.MaxPooling2D object at 0x150683290>> could not be transformed and will be executed as-is. Please report this to the AutgoGraph team. When filing the bug, set the verbosity to 10 (on Linux, `export AUTOGRAPH_VERBOSITY=10`) and attach the full output. Cause: converting <bound method Pooling2D.call of <tensorflow.python.layers.pooling.MaxPooling2D object at 0x150683290>>: AssertionError: Bad argument number for Name: 3, expecting 4\n",
      "WARNING: Entity <bound method Pooling2D.call of <tensorflow.python.layers.pooling.MaxPooling2D object at 0x150683290>> could not be transformed and will be executed as-is. Please report this to the AutgoGraph team. When filing the bug, set the verbosity to 10 (on Linux, `export AUTOGRAPH_VERBOSITY=10`) and attach the full output. Cause: converting <bound method Pooling2D.call of <tensorflow.python.layers.pooling.MaxPooling2D object at 0x150683290>>: AssertionError: Bad argument number for Name: 3, expecting 4\n",
      "WARNING:tensorflow:Entity <bound method Conv.call of <tensorflow.python.layers.convolutional.Conv2D object at 0x150332a50>> could not be transformed and will be executed as-is. Please report this to the AutgoGraph team. When filing the bug, set the verbosity to 10 (on Linux, `export AUTOGRAPH_VERBOSITY=10`) and attach the full output. Cause: converting <bound method Conv.call of <tensorflow.python.layers.convolutional.Conv2D object at 0x150332a50>>: AssertionError: Bad argument number for Name: 3, expecting 4\n",
      "WARNING: Entity <bound method Conv.call of <tensorflow.python.layers.convolutional.Conv2D object at 0x150332a50>> could not be transformed and will be executed as-is. Please report this to the AutgoGraph team. When filing the bug, set the verbosity to 10 (on Linux, `export AUTOGRAPH_VERBOSITY=10`) and attach the full output. Cause: converting <bound method Conv.call of <tensorflow.python.layers.convolutional.Conv2D object at 0x150332a50>>: AssertionError: Bad argument number for Name: 3, expecting 4\n",
      "WARNING:tensorflow:Entity <bound method Conv.call of <tensorflow.python.layers.convolutional.Conv2D object at 0x1504dc6d0>> could not be transformed and will be executed as-is. Please report this to the AutgoGraph team. When filing the bug, set the verbosity to 10 (on Linux, `export AUTOGRAPH_VERBOSITY=10`) and attach the full output. Cause: converting <bound method Conv.call of <tensorflow.python.layers.convolutional.Conv2D object at 0x1504dc6d0>>: AssertionError: Bad argument number for Name: 3, expecting 4\n",
      "WARNING: Entity <bound method Conv.call of <tensorflow.python.layers.convolutional.Conv2D object at 0x1504dc6d0>> could not be transformed and will be executed as-is. Please report this to the AutgoGraph team. When filing the bug, set the verbosity to 10 (on Linux, `export AUTOGRAPH_VERBOSITY=10`) and attach the full output. Cause: converting <bound method Conv.call of <tensorflow.python.layers.convolutional.Conv2D object at 0x1504dc6d0>>: AssertionError: Bad argument number for Name: 3, expecting 4\n"
     ]
    },
    {
     "name": "stdout",
     "output_type": "stream",
     "text": [
      "WARNING:tensorflow:Entity <bound method Conv.call of <tensorflow.python.layers.convolutional.Conv2D object at 0x14ffbdcd0>> could not be transformed and will be executed as-is. Please report this to the AutgoGraph team. When filing the bug, set the verbosity to 10 (on Linux, `export AUTOGRAPH_VERBOSITY=10`) and attach the full output. Cause: converting <bound method Conv.call of <tensorflow.python.layers.convolutional.Conv2D object at 0x14ffbdcd0>>: AssertionError: Bad argument number for Name: 3, expecting 4\n",
      "WARNING: Entity <bound method Conv.call of <tensorflow.python.layers.convolutional.Conv2D object at 0x14ffbdcd0>> could not be transformed and will be executed as-is. Please report this to the AutgoGraph team. When filing the bug, set the verbosity to 10 (on Linux, `export AUTOGRAPH_VERBOSITY=10`) and attach the full output. Cause: converting <bound method Conv.call of <tensorflow.python.layers.convolutional.Conv2D object at 0x14ffbdcd0>>: AssertionError: Bad argument number for Name: 3, expecting 4\n",
      "WARNING:tensorflow:Entity <bound method Conv.call of <tensorflow.python.layers.convolutional.Conv2D object at 0x15029aa90>> could not be transformed and will be executed as-is. Please report this to the AutgoGraph team. When filing the bug, set the verbosity to 10 (on Linux, `export AUTOGRAPH_VERBOSITY=10`) and attach the full output. Cause: converting <bound method Conv.call of <tensorflow.python.layers.convolutional.Conv2D object at 0x15029aa90>>: AssertionError: Bad argument number for Name: 3, expecting 4\n",
      "WARNING: Entity <bound method Conv.call of <tensorflow.python.layers.convolutional.Conv2D object at 0x15029aa90>> could not be transformed and will be executed as-is. Please report this to the AutgoGraph team. When filing the bug, set the verbosity to 10 (on Linux, `export AUTOGRAPH_VERBOSITY=10`) and attach the full output. Cause: converting <bound method Conv.call of <tensorflow.python.layers.convolutional.Conv2D object at 0x15029aa90>>: AssertionError: Bad argument number for Name: 3, expecting 4\n",
      "WARNING:tensorflow:Entity <bound method LSTMCell.call of <tensorflow.python.ops.rnn_cell_impl.LSTMCell object at 0x150823fd0>> could not be transformed and will be executed as-is. Please report this to the AutgoGraph team. When filing the bug, set the verbosity to 10 (on Linux, `export AUTOGRAPH_VERBOSITY=10`) and attach the full output. Cause: converting <bound method LSTMCell.call of <tensorflow.python.ops.rnn_cell_impl.LSTMCell object at 0x150823fd0>>: AttributeError: module 'gast' has no attribute 'Num'\n",
      "WARNING: Entity <bound method LSTMCell.call of <tensorflow.python.ops.rnn_cell_impl.LSTMCell object at 0x150823fd0>> could not be transformed and will be executed as-is. Please report this to the AutgoGraph team. When filing the bug, set the verbosity to 10 (on Linux, `export AUTOGRAPH_VERBOSITY=10`) and attach the full output. Cause: converting <bound method LSTMCell.call of <tensorflow.python.ops.rnn_cell_impl.LSTMCell object at 0x150823fd0>>: AttributeError: module 'gast' has no attribute 'Num'\n",
      "WARNING:tensorflow:Entity <bound method LSTMCell.call of <tensorflow.python.ops.rnn_cell_impl.LSTMCell object at 0x1501d5dd0>> could not be transformed and will be executed as-is. Please report this to the AutgoGraph team. When filing the bug, set the verbosity to 10 (on Linux, `export AUTOGRAPH_VERBOSITY=10`) and attach the full output. Cause: converting <bound method LSTMCell.call of <tensorflow.python.ops.rnn_cell_impl.LSTMCell object at 0x1501d5dd0>>: AttributeError: module 'gast' has no attribute 'Num'\n",
      "WARNING: Entity <bound method LSTMCell.call of <tensorflow.python.ops.rnn_cell_impl.LSTMCell object at 0x1501d5dd0>> could not be transformed and will be executed as-is. Please report this to the AutgoGraph team. When filing the bug, set the verbosity to 10 (on Linux, `export AUTOGRAPH_VERBOSITY=10`) and attach the full output. Cause: converting <bound method LSTMCell.call of <tensorflow.python.ops.rnn_cell_impl.LSTMCell object at 0x1501d5dd0>>: AttributeError: module 'gast' has no attribute 'Num'\n",
      "INFO:tensorflow:Restoring parameters from new_ctpn/checkpoints_mlt/ocr_ctpn_50000.ckpt\n",
      "Load model from \"./train/models/pytorch-crnn.pth\" ...\n",
      "Done!\n",
      "2020/04/1813:03:30\n",
      "2020/04/18\n",
      "上海合生汇工坊店\n",
      "VIP5:13022117676结万5\n",
      "孙小文\n",
      "00000886\n",
      "135/76A8801880.0005455400.000048000\n",
      "YCSX340193HRA\n",
      "175/96A128011280.000.5313600.0000680.00\n",
      "YJK440042FMM\n",
      "175/74A108011080.0005370500.0000580.00\n",
      "YCDP340172FWA\n",
      "M6801680.000.6000272.0000408.00\n",
      "YSPC540122PFA\n",
      "MSZS54405MCM\n",
      "175/92A258012580.000.60001032.0001548.00\n",
      "12580.00060001032.0001548.00\n",
      "42198011980.0006000792.00001188.00\n",
      "MLTP16467KBA\n",
      "上海市杨消区翔殷路1099号上海合13524281415\n",
      "上海合生汇工坊店\n",
      "2020/04/18\n",
      "2020/04/1813:03:30\n",
      "00000886\n",
      "YIP市:13022117676结卡\n",
      "小文\n",
      "185/98A108011080.000.6000432.0000648.00\n",
      "YCVW310186HVA\n",
      "寸乐号行众金否单位流水号\n",
      "银厅卡5500.00元/张nul\n",
      "零售金额:9560.00总数7总扣额4028.00\n",
      "地金32.00元/张mul\n",
      "实收:5532.00舍零:0.00\n",
      "上海市场浦区翔殷临1099号上海合13524281415\n",
      "WARNING:tensorflow:Entity <bound method Conv.call of <tensorflow.python.layers.convolutional.Conv2D object at 0x1501498d0>> could not be transformed and will be executed as-is. Please report this to the AutgoGraph team. When filing the bug, set the verbosity to 10 (on Linux, `export AUTOGRAPH_VERBOSITY=10`) and attach the full output. Cause: converting <bound method Conv.call of <tensorflow.python.layers.convolutional.Conv2D object at 0x1501498d0>>: AssertionError: Bad argument number for Name: 3, expecting 4\n",
      "WARNING: Entity <bound method Conv.call of <tensorflow.python.layers.convolutional.Conv2D object at 0x1501498d0>> could not be transformed and will be executed as-is. Please report this to the AutgoGraph team. When filing the bug, set the verbosity to 10 (on Linux, `export AUTOGRAPH_VERBOSITY=10`) and attach the full output. Cause: converting <bound method Conv.call of <tensorflow.python.layers.convolutional.Conv2D object at 0x1501498d0>>: AssertionError: Bad argument number for Name: 3, expecting 4\n",
      "WARNING:tensorflow:Entity <bound method Conv.call of <tensorflow.python.layers.convolutional.Conv2D object at 0x150149dd0>> could not be transformed and will be executed as-is. Please report this to the AutgoGraph team. When filing the bug, set the verbosity to 10 (on Linux, `export AUTOGRAPH_VERBOSITY=10`) and attach the full output. Cause: converting <bound method Conv.call of <tensorflow.python.layers.convolutional.Conv2D object at 0x150149dd0>>: AssertionError: Bad argument number for Name: 3, expecting 4\n",
      "WARNING: Entity <bound method Conv.call of <tensorflow.python.layers.convolutional.Conv2D object at 0x150149dd0>> could not be transformed and will be executed as-is. Please report this to the AutgoGraph team. When filing the bug, set the verbosity to 10 (on Linux, `export AUTOGRAPH_VERBOSITY=10`) and attach the full output. Cause: converting <bound method Conv.call of <tensorflow.python.layers.convolutional.Conv2D object at 0x150149dd0>>: AssertionError: Bad argument number for Name: 3, expecting 4\n",
      "WARNING:tensorflow:Entity <bound method Pooling2D.call of <tensorflow.python.layers.pooling.MaxPooling2D object at 0x150281c50>> could not be transformed and will be executed as-is. Please report this to the AutgoGraph team. When filing the bug, set the verbosity to 10 (on Linux, `export AUTOGRAPH_VERBOSITY=10`) and attach the full output. Cause: converting <bound method Pooling2D.call of <tensorflow.python.layers.pooling.MaxPooling2D object at 0x150281c50>>: AssertionError: Bad argument number for Name: 3, expecting 4\n",
      "WARNING: Entity <bound method Pooling2D.call of <tensorflow.python.layers.pooling.MaxPooling2D object at 0x150281c50>> could not be transformed and will be executed as-is. Please report this to the AutgoGraph team. When filing the bug, set the verbosity to 10 (on Linux, `export AUTOGRAPH_VERBOSITY=10`) and attach the full output. Cause: converting <bound method Pooling2D.call of <tensorflow.python.layers.pooling.MaxPooling2D object at 0x150281c50>>: AssertionError: Bad argument number for Name: 3, expecting 4\n",
      "WARNING:tensorflow:Entity <bound method Conv.call of <tensorflow.python.layers.convolutional.Conv2D object at 0x150149490>> could not be transformed and will be executed as-is. Please report this to the AutgoGraph team. When filing the bug, set the verbosity to 10 (on Linux, `export AUTOGRAPH_VERBOSITY=10`) and attach the full output. Cause: converting <bound method Conv.call of <tensorflow.python.layers.convolutional.Conv2D object at 0x150149490>>: AssertionError: Bad argument number for Name: 3, expecting 4\n"
     ]
    },
    {
     "name": "stdout",
     "output_type": "stream",
     "text": [
      "WARNING: Entity <bound method Conv.call of <tensorflow.python.layers.convolutional.Conv2D object at 0x150149490>> could not be transformed and will be executed as-is. Please report this to the AutgoGraph team. When filing the bug, set the verbosity to 10 (on Linux, `export AUTOGRAPH_VERBOSITY=10`) and attach the full output. Cause: converting <bound method Conv.call of <tensorflow.python.layers.convolutional.Conv2D object at 0x150149490>>: AssertionError: Bad argument number for Name: 3, expecting 4\n",
      "WARNING:tensorflow:Entity <bound method Conv.call of <tensorflow.python.layers.convolutional.Conv2D object at 0x150149410>> could not be transformed and will be executed as-is. Please report this to the AutgoGraph team. When filing the bug, set the verbosity to 10 (on Linux, `export AUTOGRAPH_VERBOSITY=10`) and attach the full output. Cause: converting <bound method Conv.call of <tensorflow.python.layers.convolutional.Conv2D object at 0x150149410>>: AssertionError: Bad argument number for Name: 3, expecting 4\n",
      "WARNING: Entity <bound method Conv.call of <tensorflow.python.layers.convolutional.Conv2D object at 0x150149410>> could not be transformed and will be executed as-is. Please report this to the AutgoGraph team. When filing the bug, set the verbosity to 10 (on Linux, `export AUTOGRAPH_VERBOSITY=10`) and attach the full output. Cause: converting <bound method Conv.call of <tensorflow.python.layers.convolutional.Conv2D object at 0x150149410>>: AssertionError: Bad argument number for Name: 3, expecting 4\n",
      "WARNING:tensorflow:Entity <bound method Pooling2D.call of <tensorflow.python.layers.pooling.MaxPooling2D object at 0x150c33150>> could not be transformed and will be executed as-is. Please report this to the AutgoGraph team. When filing the bug, set the verbosity to 10 (on Linux, `export AUTOGRAPH_VERBOSITY=10`) and attach the full output. Cause: converting <bound method Pooling2D.call of <tensorflow.python.layers.pooling.MaxPooling2D object at 0x150c33150>>: AssertionError: Bad argument number for Name: 3, expecting 4\n",
      "WARNING: Entity <bound method Pooling2D.call of <tensorflow.python.layers.pooling.MaxPooling2D object at 0x150c33150>> could not be transformed and will be executed as-is. Please report this to the AutgoGraph team. When filing the bug, set the verbosity to 10 (on Linux, `export AUTOGRAPH_VERBOSITY=10`) and attach the full output. Cause: converting <bound method Pooling2D.call of <tensorflow.python.layers.pooling.MaxPooling2D object at 0x150c33150>>: AssertionError: Bad argument number for Name: 3, expecting 4\n",
      "WARNING:tensorflow:Entity <bound method Conv.call of <tensorflow.python.layers.convolutional.Conv2D object at 0x14fffb190>> could not be transformed and will be executed as-is. Please report this to the AutgoGraph team. When filing the bug, set the verbosity to 10 (on Linux, `export AUTOGRAPH_VERBOSITY=10`) and attach the full output. Cause: converting <bound method Conv.call of <tensorflow.python.layers.convolutional.Conv2D object at 0x14fffb190>>: AssertionError: Bad argument number for Name: 3, expecting 4\n",
      "WARNING: Entity <bound method Conv.call of <tensorflow.python.layers.convolutional.Conv2D object at 0x14fffb190>> could not be transformed and will be executed as-is. Please report this to the AutgoGraph team. When filing the bug, set the verbosity to 10 (on Linux, `export AUTOGRAPH_VERBOSITY=10`) and attach the full output. Cause: converting <bound method Conv.call of <tensorflow.python.layers.convolutional.Conv2D object at 0x14fffb190>>: AssertionError: Bad argument number for Name: 3, expecting 4\n",
      "WARNING:tensorflow:Entity <bound method Conv.call of <tensorflow.python.layers.convolutional.Conv2D object at 0x150149490>> could not be transformed and will be executed as-is. Please report this to the AutgoGraph team. When filing the bug, set the verbosity to 10 (on Linux, `export AUTOGRAPH_VERBOSITY=10`) and attach the full output. Cause: converting <bound method Conv.call of <tensorflow.python.layers.convolutional.Conv2D object at 0x150149490>>: AssertionError: Bad argument number for Name: 3, expecting 4\n",
      "WARNING: Entity <bound method Conv.call of <tensorflow.python.layers.convolutional.Conv2D object at 0x150149490>> could not be transformed and will be executed as-is. Please report this to the AutgoGraph team. When filing the bug, set the verbosity to 10 (on Linux, `export AUTOGRAPH_VERBOSITY=10`) and attach the full output. Cause: converting <bound method Conv.call of <tensorflow.python.layers.convolutional.Conv2D object at 0x150149490>>: AssertionError: Bad argument number for Name: 3, expecting 4\n",
      "WARNING:tensorflow:Entity <bound method Conv.call of <tensorflow.python.layers.convolutional.Conv2D object at 0x15087f390>> could not be transformed and will be executed as-is. Please report this to the AutgoGraph team. When filing the bug, set the verbosity to 10 (on Linux, `export AUTOGRAPH_VERBOSITY=10`) and attach the full output. Cause: converting <bound method Conv.call of <tensorflow.python.layers.convolutional.Conv2D object at 0x15087f390>>: AssertionError: Bad argument number for Name: 3, expecting 4\n",
      "WARNING: Entity <bound method Conv.call of <tensorflow.python.layers.convolutional.Conv2D object at 0x15087f390>> could not be transformed and will be executed as-is. Please report this to the AutgoGraph team. When filing the bug, set the verbosity to 10 (on Linux, `export AUTOGRAPH_VERBOSITY=10`) and attach the full output. Cause: converting <bound method Conv.call of <tensorflow.python.layers.convolutional.Conv2D object at 0x15087f390>>: AssertionError: Bad argument number for Name: 3, expecting 4\n",
      "WARNING:tensorflow:Entity <bound method Pooling2D.call of <tensorflow.python.layers.pooling.MaxPooling2D object at 0x14ffff450>> could not be transformed and will be executed as-is. Please report this to the AutgoGraph team. When filing the bug, set the verbosity to 10 (on Linux, `export AUTOGRAPH_VERBOSITY=10`) and attach the full output. Cause: converting <bound method Pooling2D.call of <tensorflow.python.layers.pooling.MaxPooling2D object at 0x14ffff450>>: AssertionError: Bad argument number for Name: 3, expecting 4\n",
      "WARNING: Entity <bound method Pooling2D.call of <tensorflow.python.layers.pooling.MaxPooling2D object at 0x14ffff450>> could not be transformed and will be executed as-is. Please report this to the AutgoGraph team. When filing the bug, set the verbosity to 10 (on Linux, `export AUTOGRAPH_VERBOSITY=10`) and attach the full output. Cause: converting <bound method Pooling2D.call of <tensorflow.python.layers.pooling.MaxPooling2D object at 0x14ffff450>>: AssertionError: Bad argument number for Name: 3, expecting 4\n",
      "WARNING:tensorflow:Entity <bound method Conv.call of <tensorflow.python.layers.convolutional.Conv2D object at 0x15030bfd0>> could not be transformed and will be executed as-is. Please report this to the AutgoGraph team. When filing the bug, set the verbosity to 10 (on Linux, `export AUTOGRAPH_VERBOSITY=10`) and attach the full output. Cause: converting <bound method Conv.call of <tensorflow.python.layers.convolutional.Conv2D object at 0x15030bfd0>>: AssertionError: Bad argument number for Name: 3, expecting 4\n",
      "WARNING: Entity <bound method Conv.call of <tensorflow.python.layers.convolutional.Conv2D object at 0x15030bfd0>> could not be transformed and will be executed as-is. Please report this to the AutgoGraph team. When filing the bug, set the verbosity to 10 (on Linux, `export AUTOGRAPH_VERBOSITY=10`) and attach the full output. Cause: converting <bound method Conv.call of <tensorflow.python.layers.convolutional.Conv2D object at 0x15030bfd0>>: AssertionError: Bad argument number for Name: 3, expecting 4\n",
      "WARNING:tensorflow:Entity <bound method Conv.call of <tensorflow.python.layers.convolutional.Conv2D object at 0x14f5a6ad0>> could not be transformed and will be executed as-is. Please report this to the AutgoGraph team. When filing the bug, set the verbosity to 10 (on Linux, `export AUTOGRAPH_VERBOSITY=10`) and attach the full output. Cause: converting <bound method Conv.call of <tensorflow.python.layers.convolutional.Conv2D object at 0x14f5a6ad0>>: AssertionError: Bad argument number for Name: 3, expecting 4\n"
     ]
    },
    {
     "name": "stdout",
     "output_type": "stream",
     "text": [
      "WARNING: Entity <bound method Conv.call of <tensorflow.python.layers.convolutional.Conv2D object at 0x14f5a6ad0>> could not be transformed and will be executed as-is. Please report this to the AutgoGraph team. When filing the bug, set the verbosity to 10 (on Linux, `export AUTOGRAPH_VERBOSITY=10`) and attach the full output. Cause: converting <bound method Conv.call of <tensorflow.python.layers.convolutional.Conv2D object at 0x14f5a6ad0>>: AssertionError: Bad argument number for Name: 3, expecting 4\n",
      "WARNING:tensorflow:Entity <bound method Conv.call of <tensorflow.python.layers.convolutional.Conv2D object at 0x150149050>> could not be transformed and will be executed as-is. Please report this to the AutgoGraph team. When filing the bug, set the verbosity to 10 (on Linux, `export AUTOGRAPH_VERBOSITY=10`) and attach the full output. Cause: converting <bound method Conv.call of <tensorflow.python.layers.convolutional.Conv2D object at 0x150149050>>: AssertionError: Bad argument number for Name: 3, expecting 4\n",
      "WARNING: Entity <bound method Conv.call of <tensorflow.python.layers.convolutional.Conv2D object at 0x150149050>> could not be transformed and will be executed as-is. Please report this to the AutgoGraph team. When filing the bug, set the verbosity to 10 (on Linux, `export AUTOGRAPH_VERBOSITY=10`) and attach the full output. Cause: converting <bound method Conv.call of <tensorflow.python.layers.convolutional.Conv2D object at 0x150149050>>: AssertionError: Bad argument number for Name: 3, expecting 4\n",
      "WARNING:tensorflow:Entity <bound method Pooling2D.call of <tensorflow.python.layers.pooling.MaxPooling2D object at 0x150689ed0>> could not be transformed and will be executed as-is. Please report this to the AutgoGraph team. When filing the bug, set the verbosity to 10 (on Linux, `export AUTOGRAPH_VERBOSITY=10`) and attach the full output. Cause: converting <bound method Pooling2D.call of <tensorflow.python.layers.pooling.MaxPooling2D object at 0x150689ed0>>: AssertionError: Bad argument number for Name: 3, expecting 4\n",
      "WARNING: Entity <bound method Pooling2D.call of <tensorflow.python.layers.pooling.MaxPooling2D object at 0x150689ed0>> could not be transformed and will be executed as-is. Please report this to the AutgoGraph team. When filing the bug, set the verbosity to 10 (on Linux, `export AUTOGRAPH_VERBOSITY=10`) and attach the full output. Cause: converting <bound method Pooling2D.call of <tensorflow.python.layers.pooling.MaxPooling2D object at 0x150689ed0>>: AssertionError: Bad argument number for Name: 3, expecting 4\n",
      "WARNING:tensorflow:Entity <bound method Conv.call of <tensorflow.python.layers.convolutional.Conv2D object at 0x15030ba50>> could not be transformed and will be executed as-is. Please report this to the AutgoGraph team. When filing the bug, set the verbosity to 10 (on Linux, `export AUTOGRAPH_VERBOSITY=10`) and attach the full output. Cause: converting <bound method Conv.call of <tensorflow.python.layers.convolutional.Conv2D object at 0x15030ba50>>: AssertionError: Bad argument number for Name: 3, expecting 4\n",
      "WARNING: Entity <bound method Conv.call of <tensorflow.python.layers.convolutional.Conv2D object at 0x15030ba50>> could not be transformed and will be executed as-is. Please report this to the AutgoGraph team. When filing the bug, set the verbosity to 10 (on Linux, `export AUTOGRAPH_VERBOSITY=10`) and attach the full output. Cause: converting <bound method Conv.call of <tensorflow.python.layers.convolutional.Conv2D object at 0x15030ba50>>: AssertionError: Bad argument number for Name: 3, expecting 4\n",
      "WARNING:tensorflow:Entity <bound method Conv.call of <tensorflow.python.layers.convolutional.Conv2D object at 0x1509c6e90>> could not be transformed and will be executed as-is. Please report this to the AutgoGraph team. When filing the bug, set the verbosity to 10 (on Linux, `export AUTOGRAPH_VERBOSITY=10`) and attach the full output. Cause: converting <bound method Conv.call of <tensorflow.python.layers.convolutional.Conv2D object at 0x1509c6e90>>: AssertionError: Bad argument number for Name: 3, expecting 4\n",
      "WARNING: Entity <bound method Conv.call of <tensorflow.python.layers.convolutional.Conv2D object at 0x1509c6e90>> could not be transformed and will be executed as-is. Please report this to the AutgoGraph team. When filing the bug, set the verbosity to 10 (on Linux, `export AUTOGRAPH_VERBOSITY=10`) and attach the full output. Cause: converting <bound method Conv.call of <tensorflow.python.layers.convolutional.Conv2D object at 0x1509c6e90>>: AssertionError: Bad argument number for Name: 3, expecting 4\n",
      "WARNING:tensorflow:Entity <bound method Conv.call of <tensorflow.python.layers.convolutional.Conv2D object at 0x14fffb410>> could not be transformed and will be executed as-is. Please report this to the AutgoGraph team. When filing the bug, set the verbosity to 10 (on Linux, `export AUTOGRAPH_VERBOSITY=10`) and attach the full output. Cause: converting <bound method Conv.call of <tensorflow.python.layers.convolutional.Conv2D object at 0x14fffb410>>: AssertionError: Bad argument number for Name: 3, expecting 4\n",
      "WARNING: Entity <bound method Conv.call of <tensorflow.python.layers.convolutional.Conv2D object at 0x14fffb410>> could not be transformed and will be executed as-is. Please report this to the AutgoGraph team. When filing the bug, set the verbosity to 10 (on Linux, `export AUTOGRAPH_VERBOSITY=10`) and attach the full output. Cause: converting <bound method Conv.call of <tensorflow.python.layers.convolutional.Conv2D object at 0x14fffb410>>: AssertionError: Bad argument number for Name: 3, expecting 4\n",
      "WARNING:tensorflow:Entity <bound method Conv.call of <tensorflow.python.layers.convolutional.Conv2D object at 0x14ffff450>> could not be transformed and will be executed as-is. Please report this to the AutgoGraph team. When filing the bug, set the verbosity to 10 (on Linux, `export AUTOGRAPH_VERBOSITY=10`) and attach the full output. Cause: converting <bound method Conv.call of <tensorflow.python.layers.convolutional.Conv2D object at 0x14ffff450>>: AssertionError: Bad argument number for Name: 3, expecting 4\n",
      "WARNING: Entity <bound method Conv.call of <tensorflow.python.layers.convolutional.Conv2D object at 0x14ffff450>> could not be transformed and will be executed as-is. Please report this to the AutgoGraph team. When filing the bug, set the verbosity to 10 (on Linux, `export AUTOGRAPH_VERBOSITY=10`) and attach the full output. Cause: converting <bound method Conv.call of <tensorflow.python.layers.convolutional.Conv2D object at 0x14ffff450>>: AssertionError: Bad argument number for Name: 3, expecting 4\n",
      "WARNING:tensorflow:Entity <bound method LSTMCell.call of <tensorflow.python.ops.rnn_cell_impl.LSTMCell object at 0x14ff24f10>> could not be transformed and will be executed as-is. Please report this to the AutgoGraph team. When filing the bug, set the verbosity to 10 (on Linux, `export AUTOGRAPH_VERBOSITY=10`) and attach the full output. Cause: converting <bound method LSTMCell.call of <tensorflow.python.ops.rnn_cell_impl.LSTMCell object at 0x14ff24f10>>: AttributeError: module 'gast' has no attribute 'Num'\n",
      "WARNING: Entity <bound method LSTMCell.call of <tensorflow.python.ops.rnn_cell_impl.LSTMCell object at 0x14ff24f10>> could not be transformed and will be executed as-is. Please report this to the AutgoGraph team. When filing the bug, set the verbosity to 10 (on Linux, `export AUTOGRAPH_VERBOSITY=10`) and attach the full output. Cause: converting <bound method LSTMCell.call of <tensorflow.python.ops.rnn_cell_impl.LSTMCell object at 0x14ff24f10>>: AttributeError: module 'gast' has no attribute 'Num'\n",
      "WARNING:tensorflow:Entity <bound method LSTMCell.call of <tensorflow.python.ops.rnn_cell_impl.LSTMCell object at 0x1504ae710>> could not be transformed and will be executed as-is. Please report this to the AutgoGraph team. When filing the bug, set the verbosity to 10 (on Linux, `export AUTOGRAPH_VERBOSITY=10`) and attach the full output. Cause: converting <bound method LSTMCell.call of <tensorflow.python.ops.rnn_cell_impl.LSTMCell object at 0x1504ae710>>: AttributeError: module 'gast' has no attribute 'Num'\n",
      "WARNING: Entity <bound method LSTMCell.call of <tensorflow.python.ops.rnn_cell_impl.LSTMCell object at 0x1504ae710>> could not be transformed and will be executed as-is. Please report this to the AutgoGraph team. When filing the bug, set the verbosity to 10 (on Linux, `export AUTOGRAPH_VERBOSITY=10`) and attach the full output. Cause: converting <bound method LSTMCell.call of <tensorflow.python.ops.rnn_cell_impl.LSTMCell object at 0x1504ae710>>: AttributeError: module 'gast' has no attribute 'Num'\n"
     ]
    },
    {
     "name": "stdout",
     "output_type": "stream",
     "text": [
      "INFO:tensorflow:Restoring parameters from new_ctpn/checkpoints_mlt/ocr_ctpn_50000.ckpt\n",
      "Load model from \"./train/models/pytorch-crnn.pth\" ...\n",
      "Done!\n",
      "紫UwwA\n",
      "￥式流号I80241\n",
      "粉￥单:\n",
      "S票号:I2ala@aalleooaool\n",
      "厅小小小小京合小WP\n",
      "收凤:Is32ul\n",
      "厅iwaF\n",
      "*￥\n",
      "E证::8:l53636es\n",
      "出据日H:320W6Eulul合:110\n",
      "品总9F西款豆价扫区打5价金瓶\n",
      "找心*厅\n",
      "lAgac1lcsla133s文F小汤零312ls.c1es1es0\n",
      "兰8C302206404338文建3值3s\n",
      "销西A3(1C17055(Q5*5天4123%A19IXIR\n",
      "E8C302056404343衣优3值\n",
      "诚出2C3C2065900239EA>黑式1I3155l0s9\n",
      "销区SC3C2099:0C240ER生衣花2:惠么m128s:::23321\n",
      "付*方*\n",
      "乐余址:\n",
      "应#In:gl.aa\n",
      "保卡IIsl.m\n",
      "务费\n",
      "支付金:u9l.w\n",
      "会A￥:wxmasslcs\n",
      "找:\n",
      "备注f5-ss\n",
      "dxcpuduluul￥总关验收V时J面\n"
     ]
    }
   ],
   "source": [
    "for j, file_in in enumerate(image_files):\n",
    "    file_out = out_path+'/img_'+str(j)+'_'\n",
    "    image = cv2.imread(file_in)  # [:, :, ::-1]\n",
    "    proj,ratio,w = sg.get_proj_n_ratio(image)\n",
    "    #print(ratio)\n",
    "    bbox = []\n",
    "    text = []\n",
    "    seg_num, seg_list = sg.get_seg_list(proj,ratio,w)\n",
    "    for i in range(seg_num):\n",
    "        out = file_out+str(i)+'.png'\n",
    "        sub_img = image[seg_list[i]:seg_list[i+1],:w]\n",
    "        sub_img = sg.resize_image(sub_img)\n",
    "        result,image_framed = fengzhuang_chinese_ocr.one_img_get_text(sub_img)\n",
    "        \n",
    "        #save image\n",
    "        Image.fromarray(image_framed).save(out)\n",
    "        #show text\n",
    "        for key in result:\n",
    "            #print(result[key][1])\n",
    "            text.append(result[key][1])\n",
    "            #print('\\n')\n",
    "        #show box\n",
    "        #for key in result:\n",
    "            #print(result[key][0])\n",
    "            #bbox.append(result[key][0])\n",
    "    #print(text)\n",
    "    #print(bbox)\n",
    "    output_txt = out_path+'/img_'+str(j)+'.txt'\n",
    "    with open(output_txt,'w') as f:\n",
    "        for l in text:\n",
    "            print(l)\n",
    "            line = l+'\\r\\n'\n",
    "            f.writelines(line)"
   ]
  },
  {
   "cell_type": "code",
   "execution_count": null,
   "metadata": {},
   "outputs": [],
   "source": []
  },
  {
   "cell_type": "code",
   "execution_count": null,
   "metadata": {},
   "outputs": [],
   "source": []
  },
  {
   "cell_type": "code",
   "execution_count": null,
   "metadata": {},
   "outputs": [],
   "source": []
  },
  {
   "cell_type": "code",
   "execution_count": null,
   "metadata": {},
   "outputs": [],
   "source": []
  },
  {
   "cell_type": "markdown",
   "metadata": {},
   "source": [
    "# 多个图片"
   ]
  },
  {
   "cell_type": "code",
   "execution_count": null,
   "metadata": {},
   "outputs": [],
   "source": [
    "results, images = fengzhuang_chinese_ocr.get_text(image_files)"
   ]
  },
  {
   "cell_type": "code",
   "execution_count": null,
   "metadata": {},
   "outputs": [],
   "source": [
    "plt.imshow(images[1])"
   ]
  },
  {
   "cell_type": "code",
   "execution_count": null,
   "metadata": {},
   "outputs": [],
   "source": [
    "#检测到的文字\n",
    "for result in results:\n",
    "    for key in result:\n",
    "        print(result[key][1])"
   ]
  },
  {
   "cell_type": "code",
   "execution_count": null,
   "metadata": {},
   "outputs": [],
   "source": [
    "#box 坐标\n",
    "for result in results:\n",
    "    for key in result:\n",
    "        print(result[key][0])"
   ]
  },
  {
   "cell_type": "markdown",
   "metadata": {},
   "source": [
    "# 单个图片"
   ]
  },
  {
   "cell_type": "code",
   "execution_count": null,
   "metadata": {},
   "outputs": [],
   "source": [
    "imagePath = './test_images/img_100_0.png'"
   ]
  },
  {
   "cell_type": "code",
   "execution_count": null,
   "metadata": {},
   "outputs": [],
   "source": [
    "image = np.array(Image.open(imagePath).convert('RGB'))"
   ]
  },
  {
   "cell_type": "code",
   "execution_count": null,
   "metadata": {},
   "outputs": [],
   "source": [
    "result,image_framed = fengzhuang_chinese_ocr.one_img_get_text(image)"
   ]
  },
  {
   "cell_type": "code",
   "execution_count": null,
   "metadata": {},
   "outputs": [],
   "source": [
    "for key in result:\n",
    "    print(result[key][0])"
   ]
  },
  {
   "cell_type": "code",
   "execution_count": null,
   "metadata": {},
   "outputs": [],
   "source": [
    "result"
   ]
  },
  {
   "cell_type": "code",
   "execution_count": null,
   "metadata": {},
   "outputs": [],
   "source": [
    "for key in result:\n",
    "    a = ''\n",
    "    for i in range(8):\n",
    "        a += str(result[key][0][i])\n",
    "        a+= ' '\n",
    "    print(a)"
   ]
  },
  {
   "cell_type": "code",
   "execution_count": null,
   "metadata": {},
   "outputs": [],
   "source": [
    "for key in result:\n",
    "    print(result[key][1])"
   ]
  },
  {
   "cell_type": "code",
   "execution_count": null,
   "metadata": {},
   "outputs": [],
   "source": [
    "plt.imshow(image_framed)"
   ]
  },
  {
   "cell_type": "code",
   "execution_count": null,
   "metadata": {},
   "outputs": [],
   "source": [
    "#resPath = 'res_'+ imagePath"
   ]
  },
  {
   "cell_type": "code",
   "execution_count": null,
   "metadata": {},
   "outputs": [],
   "source": [
    "#cv2.imwrite(resPath,image_framed)"
   ]
  },
  {
   "cell_type": "code",
   "execution_count": null,
   "metadata": {},
   "outputs": [],
   "source": []
  }
 ],
 "metadata": {
  "kernelspec": {
   "display_name": "Python 3",
   "language": "python",
   "name": "python3"
  },
  "language_info": {
   "codemirror_mode": {
    "name": "ipython",
    "version": 3
   },
   "file_extension": ".py",
   "mimetype": "text/x-python",
   "name": "python",
   "nbconvert_exporter": "python",
   "pygments_lexer": "ipython3",
   "version": "3.7.4"
  }
 },
 "nbformat": 4,
 "nbformat_minor": 2
}
